<?xml version="1.0" ?>
<!-- =================================================================================== -->
<!-- |    This document was autogenerated by xacro from rsu_2dof.xacro                 | -->
<!-- |    EDITING THIS FILE BY HAND IS NOT RECOMMENDED                                 | -->
<!-- =================================================================================== -->
<robot name="rsu_2dof">
  <material name="silver">
    <color rgba="0.700 0.700 0.700 1.000"/>
  </material>
  <transmission name="ankle_pitch_tran">
    <type>transmission_interface/SimpleTransmission</type>
    <joint name="ankle_pitch">
      <hardwareInterface>hardware_interface/EffortJointInterface</hardwareInterface>
    </joint>
    <actuator name="ankle_pitch_actr">
      <hardwareInterface>hardware_interface/EffortJointInterface</hardwareInterface>
      <mechanicalReduction>1</mechanicalReduction>
    </actuator>
  </transmission>
  <transmission name="upper_crank_tran">
    <type>transmission_interface/SimpleTransmission</type>
    <joint name="upper_crank">
      <hardwareInterface>hardware_interface/EffortJointInterface</hardwareInterface>
    </joint>
    <actuator name="upper_crank_actr">
      <hardwareInterface>hardware_interface/EffortJointInterface</hardwareInterface>
      <mechanicalReduction>1</mechanicalReduction>
    </actuator>
  </transmission>
  <transmission name="lower_crank_tran">
    <type>transmission_interface/SimpleTransmission</type>
    <joint name="lower_crank">
      <hardwareInterface>hardware_interface/EffortJointInterface</hardwareInterface>
    </joint>
    <actuator name="lower_crank_actr">
      <hardwareInterface>hardware_interface/EffortJointInterface</hardwareInterface>
      <mechanicalReduction>1</mechanicalReduction>
    </actuator>
  </transmission>
  <transmission name="ankle_roll_tran">
    <type>transmission_interface/SimpleTransmission</type>
    <joint name="ankle_roll">
      <hardwareInterface>hardware_interface/EffortJointInterface</hardwareInterface>
    </joint>
    <actuator name="ankle_roll_actr">
      <hardwareInterface>hardware_interface/EffortJointInterface</hardwareInterface>
      <mechanicalReduction>1</mechanicalReduction>
    </actuator>
  </transmission>
  <gazebo>
    <plugin filename="libgazebo_ros_control.so" name="control"/>
  </gazebo>
  <gazebo reference="base_link">
    <material>Gazebo/Silver</material>
    <mu1>0.2</mu1>
    <mu2>0.2</mu2>
    <self_collide>true</self_collide>
    <gravity>true</gravity>
  </gazebo>
  <gazebo reference="ankle_1">
    <material>Gazebo/Silver</material>
    <mu1>0.2</mu1>
    <mu2>0.2</mu2>
    <self_collide>true</self_collide>
  </gazebo>
  <gazebo reference="upper_crank_1">
    <material>Gazebo/Silver</material>
    <mu1>0.2</mu1>
    <mu2>0.2</mu2>
    <self_collide>true</self_collide>
  </gazebo>
  <gazebo reference="dummy_crank_1">
    <material>Gazebo/Silver</material>
    <mu1>0.2</mu1>
    <mu2>0.2</mu2>
    <self_collide>true</self_collide>
  </gazebo>
  <gazebo reference="point_c1_1">
    <material>Gazebo/Silver</material>
    <mu1>0.2</mu1>
    <mu2>0.2</mu2>
    <self_collide>true</self_collide>
  </gazebo>
  <gazebo reference="point_c2_1">
    <material>Gazebo/Silver</material>
    <mu1>0.2</mu1>
    <mu2>0.2</mu2>
    <self_collide>true</self_collide>
  </gazebo>
  <gazebo reference="dummy_foot_1">
    <material>Gazebo/Silver</material>
    <mu1>0.2</mu1>
    <mu2>0.2</mu2>
    <self_collide>true</self_collide>
  </gazebo>
  <gazebo reference="point_u2_1">
    <material>Gazebo/Silver</material>
    <mu1>0.2</mu1>
    <mu2>0.2</mu2>
    <self_collide>true</self_collide>
  </gazebo>
  <gazebo reference="point_u1_1">
    <material>Gazebo/Silver</material>
    <mu1>0.2</mu1>
    <mu2>0.2</mu2>
    <self_collide>true</self_collide>
  </gazebo>
  <link name="base_link">
    <inertial>
      <origin rpy="0 0 0" xyz="0.0015439622046916667 -0.0013953490143151371 0.2753522165320786"/>
      <mass value="5.5773556320875155"/>
      <inertia ixx="0.031297" ixy="-1.7e-05" ixz="-0.000221" iyy="0.031125" iyz="0.00125" izz="0.005396"/>
    </inertial>
    <visual>
      <origin rpy="0 0 0" xyz="0 0 0"/>
      <geometry>
        <mesh filename="package://joystick_rsu/robot_model/meshes/base_link.stl" scale="0.001 0.001 0.001"/>
      </geometry>
      <material name="silver"/>
    </visual>
    <collision>
      <origin rpy="0 0 0" xyz="0 0 0"/>
      <geometry>
        <mesh filename="package://joystick_rsu/robot_model/meshes/base_link.stl" scale="0.001 0.001 0.001"/>
      </geometry>
    </collision>
  </link>
  <link name="ankle_1">
    <inertial>
      <origin rpy="0 0 0" xyz="-1.6814828670667383e-07 -0.01449979082811163 1.3319298819425285e-07"/>
      <mass value="0.06598347385516058"/>
      <inertia ixx="1.1e-05" ixy="-0.0" ixz="0.0" iyy="6e-06" iyz="-0.0" izz="1e-05"/>
    </inertial>
    <visual>
      <origin rpy="0 0 0" xyz="7.7e-05 -0.013376 -0.125112"/>
      <geometry>
        <mesh filename="package://joystick_rsu/robot_model/meshes/ankle_1.stl" scale="0.001 0.001 0.001"/>
      </geometry>
      <material name="silver"/>
    </visual>
    <collision>
      <origin rpy="0 0 0" xyz="7.7e-05 -0.013376 -0.125112"/>
      <geometry>
        <mesh filename="package://joystick_rsu/robot_model/meshes/ankle_1.stl" scale="0.001 0.001 0.001"/>
      </geometry>
    </collision>
  </link>
  <link name="upper_crank_1">
    <inertial>
      <origin rpy="0 0 0" xyz="-0.006543704766420746 0.008551997179017213 1.331932131809488e-07"/>
      <mass value="0.07910975839927854"/>
      <inertia ixx="1e-05" ixy="3e-06" ixz="0.0" iyy="2.3e-05" iyz="0.0" izz="1.9e-05"/>
    </inertial>
    <visual>
      <origin rpy="0 0 0" xyz="7.7e-05 -0.016876 -0.295112"/>
      <geometry>
        <mesh filename="package://joystick_rsu/robot_model/meshes/upper_crank_1.stl" scale="0.001 0.001 0.001"/>
      </geometry>
      <material name="silver"/>
    </visual>
    <collision>
      <origin rpy="0 0 0" xyz="7.7e-05 -0.016876 -0.295112"/>
      <geometry>
        <mesh filename="package://joystick_rsu/robot_model/meshes/upper_crank_1.stl" scale="0.001 0.001 0.001"/>
      </geometry>
    </collision>
  </link>
  <link name="dummy_crank_1">
    <inertial>
      <origin rpy="0 0 0" xyz="-0.00654370476714048 -0.00855157883751815 1.3319265640410194e-07"/>
      <mass value="0.07910975839928247"/>
      <inertia ixx="1e-05" ixy="-3e-06" ixz="-0.0" iyy="2.3e-05" iyz="0.0" izz="1.9e-05"/>
    </inertial>
    <visual>
      <origin rpy="0 0 0" xyz="7.7e-05 0.019124 -0.207112"/>
      <geometry>
        <mesh filename="package://joystick_rsu/robot_model/meshes/dummy_crank_1.stl" scale="0.001 0.001 0.001"/>
      </geometry>
      <material name="silver"/>
    </visual>
    <collision>
      <origin rpy="0 0 0" xyz="7.7e-05 0.019124 -0.207112"/>
      <geometry>
        <mesh filename="package://joystick_rsu/robot_model/meshes/dummy_crank_1.stl" scale="0.001 0.001 0.001"/>
      </geometry>
    </collision>
  </link>
  <link name="point_c1_1">
    <inertial>
      <origin rpy="0 0 0" xyz="-1.706661195595427e-07 7.091764866462569e-07 0.00020942530882356314"/>
      <mass value="1.902707681457099e-07"/>
      <inertia ixx="0.0" ixy="-0.0" ixz="-0.0" iyy="0.0" iyz="0.0" izz="0.0"/>
    </inertial>
    <visual>
      <origin rpy="0 0 0" xyz="0.030077 -0.038876 -0.295112"/>
      <geometry>
        <mesh filename="package://joystick_rsu/robot_model/meshes/point_c1_1.stl" scale="0.001 0.001 0.001"/>
      </geometry>
      <material name="silver"/>
    </visual>
    <collision>
      <origin rpy="0 0 0" xyz="0.030077 -0.038876 -0.295112"/>
      <geometry>
        <mesh filename="package://joystick_rsu/robot_model/meshes/point_c1_1.stl" scale="0.001 0.001 0.001"/>
      </geometry>
    </collision>
  </link>
  <link name="point_c2_1">
    <inertial>
      <origin rpy="0 0 0" xyz="-1.656280141787425e-07 -2.908227270462249e-07 -0.00020915892277573178"/>
      <mass value="1.902707681457099e-07"/>
      <inertia ixx="0.0" ixy="0.0" ixz="-0.0" iyy="0.0" iyz="-0.0" izz="0.0"/>
    </inertial>
    <visual>
      <origin rpy="0 0 0" xyz="0.030077 0.041124 -0.207112"/>
      <geometry>
        <mesh filename="package://joystick_rsu/robot_model/meshes/point_c2_1.stl" scale="0.001 0.001 0.001"/>
      </geometry>
      <material name="silver"/>
    </visual>
    <collision>
      <origin rpy="0 0 0" xyz="0.030077 0.041124 -0.207112"/>
      <geometry>
        <mesh filename="package://joystick_rsu/robot_model/meshes/point_c2_1.stl" scale="0.001 0.001 0.001"/>
      </geometry>
    </collision>
  </link>
  <link name="dummy_foot_1">
    <inertial>
      <origin rpy="0 0 0" xyz="-0.002243988298611471 2.0917188390417486e-07 -0.04519072975889085"/>
      <mass value="2.100649409145815"/>
      <inertia ixx="0.00186" ixy="0.0" ixz="0.000201" iyy="0.003983" iyz="0.0" izz="0.005284"/>
    </inertial>
    <visual>
      <origin rpy="0 0 0" xyz="-0.011923 0.001124 -0.125112"/>
      <geometry>
        <mesh filename="package://joystick_rsu/robot_model/meshes/dummy_foot_1.stl" scale="0.001 0.001 0.001"/>
      </geometry>
      <material name="silver"/>
    </visual>
    <collision>
      <origin rpy="0 0 0" xyz="-0.011923 0.001124 -0.125112"/>
      <geometry>
        <mesh filename="package://joystick_rsu/robot_model/meshes/dummy_foot_1.stl" scale="0.001 0.001 0.001"/>
      </geometry>
    </collision>
  </link>
  <link name="point_u2_1">
    <inertial>
      <origin rpy="0 0 0" xyz="-1.7066754771921655e-07 -2.908219636638121e-07 0.00020942530832071538"/>
      <mass value="1.902707681457099e-07"/>
      <inertia ixx="0.0" ixy="-0.0" ixz="-0.0" iyy="0.0" iyz="0.0" izz="0.0"/>
    </inertial>
    <visual>
      <origin rpy="0 0 0" xyz="0.030077 0.037124 -0.125112"/>
      <geometry>
        <mesh filename="package://joystick_rsu/robot_model/meshes/point_u2_1.stl" scale="0.001 0.001 0.001"/>
      </geometry>
      <material name="silver"/>
    </visual>
    <collision>
      <origin rpy="0 0 0" xyz="0.030077 0.037124 -0.125112"/>
      <geometry>
        <mesh filename="package://joystick_rsu/robot_model/meshes/point_u2_1.stl" scale="0.001 0.001 0.001"/>
      </geometry>
    </collision>
  </link>
  <link name="point_u1_1">
    <inertial>
      <origin rpy="0 0 0" xyz="-1.7066751797564783e-07 7.091780363441269e-07 0.00020942530831527528"/>
      <mass value="1.902707681457099e-07"/>
      <inertia ixx="0.0" ixy="-0.0" ixz="-0.0" iyy="0.0" iyz="0.0" izz="0.0"/>
    </inertial>
    <visual>
      <origin rpy="0 0 0" xyz="0.030077 -0.034876 -0.125112"/>
      <geometry>
        <mesh filename="package://joystick_rsu/robot_model/meshes/point_u1_1.stl" scale="0.001 0.001 0.001"/>
      </geometry>
      <material name="silver"/>
    </visual>
    <collision>
      <origin rpy="0 0 0" xyz="0.030077 -0.034876 -0.125112"/>
      <geometry>
        <mesh filename="package://joystick_rsu/robot_model/meshes/point_u1_1.stl" scale="0.001 0.001 0.001"/>
      </geometry>
    </collision>
  </link>
  <joint name="ankle_pitch" type="continuous">
    <origin rpy="0 0 0" xyz="-7.7e-05 0.013376 0.125112"/>
    <parent link="base_link"/>
    <child link="ankle_1"/>
    <axis xyz="0.0 1.0 0.0"/>
  </joint>
  <joint name="upper_crank" type="continuous">
    <origin rpy="0 0 0" xyz="-7.7e-05 0.016876 0.295112"/>
    <parent link="base_link"/>
    <child link="upper_crank_1"/>
    <axis xyz="0.0 1.0 0.0"/>
  </joint>
  <joint name="lower_crank" type="continuous">
    <origin rpy="0 0 0" xyz="-7.7e-05 -0.019124 0.207112"/>
    <parent link="base_link"/>
    <child link="dummy_crank_1"/>
    <axis xyz="-0.0 -1.0 -0.0"/>
  </joint>
  <joint name="rigid_c1" type="fixed">
    <origin rpy="0 0 0" xyz="-0.03 0.022 0.0"/>
    <parent link="upper_crank_1"/>
    <child link="point_c1_1"/>
  </joint>
  <joint name="rigid_c2" type="fixed">
    <origin rpy="0 0 0" xyz="-0.03 -0.022 0.0"/>
    <parent link="dummy_crank_1"/>
    <child link="point_c2_1"/>
  </joint>
  <joint name="ankle_roll" type="continuous">
    <origin rpy="0 0 0" xyz="0.012 -0.0145 0.0"/>
    <parent link="ankle_1"/>
    <child link="dummy_foot_1"/>
    <axis xyz="1.0 0.0 0.0"/>
  </joint>
  <joint name="rigid_u2" type="fixed">
    <origin rpy="0 0 0" xyz="-0.042 -0.036 0.0"/>
    <parent link="dummy_foot_1"/>
    <child link="point_u2_1"/>
  </joint>
  <joint name="rigid_u1" type="fixed">
    <origin rpy="0 0 0" xyz="-0.042 0.036 0.0"/>
    <parent link="dummy_foot_1"/>
    <child link="point_u1_1"/>
  </joint>
</robot>
